Workbook

Sheet Forecast
A1: Fuente | B1: https://www.cenace.gob.mx/Docs/16_MARCOREGULATORIO/Prodecen/20%202024-2038%20Cap%C3%ADtulos%201%20al%206.pdf
A2: FIGURA 4.3 EVOLUCIÓN ESPERADA DE LA CAPACIDAD INSTALADA ACUMULADA POR TECNOLOGÍA, 2024-2038 (MW) | K2: pg 91
A3: 2023 data | B3: https://energia.conahcyt.mx/planeas/electricidad/capacidad-generacion
A4: Solar | B4: 7211 | C4: MW | W4: HISTORICAL
A5: Wind | B5: 7462 | C5: MW | G5: Type | H5: 2024 | I5: =+H5+1 -> 2025 | J5: =+I5+1 -> 2026 | K5: =+J5+1 -> 2027 | L5: =+K5+1 -> 2028 | M5: =+L5+1 -> 2029 | N5: =+M5+1 -> 2030 | O5: =+N5+1 -> 2031 | P5: =+O5+1 -> 2032 | ... V5: =+U5+1 -> 2038 | W5: 2013 | X5: =+W5+1 -> 2014 | Y5: =+X5+1 -> 2015 | Z5: =+Y5+1 -> 2016 | AA5: =+Z5+1 -> 2017 | AB5: =+AA5+1 -> 2018 | AC5: =+AB5+1 -> 2019 | AD5: =+AC5+1 -> 2020 | AE5: =+AD5+1 -> 2021 | ... AG5: =+AF5+1 -> 2023
F6: MW | G6: Wind | H6: =+(H29-H30)*1000 -> 7500 | I6: =+(I28-I30)*1000 -> 8500 | J6: =+(J28-J29)*1000 -> 9000 | K6: =+(K27-K29)*1000 -> 12000 | L6: =+(L26-L28)*1000 -> 15000 | M6: =+(M25-M27)*1000 -> 17000 | N6: =+(N25-N27)*1000 -> 18000 | O6: =+(O24-O27)*1000 -> 21000 | P6: =+(P23-P27)*1000 -> 22000 | Q6: =+(Q23-Q27)*1000 -> 23000 | R6: =+(R23-R27)*1000 -> 24000 | S6: =+(S22-S26)*1000 -> 26000 | T6: =+(T21-T26)*1000 -> 29000 | U6: =+(U20-U26)*1000 -> 30000 | V6: =+(V20-V26)*1000 -> 33000 | W6: =+Historical!E5 -> 1959 | X6: =+Historical!F5 -> 2655 | Y6: =+Historical!G5 -> 3233 | Z6: =+Historical!H5 -> 4009 | AA6: =+Historical!I5 -> 4474 | AB6: =+Historical!J5 -> 4677 | AC6: =+Historical!K5 -> 5970 | AD6: =+Historical!L5 -> 6654 | ... AG6: =+Historical!O5 -> 7462
G7: Solar | H7: =+(H33-H34)*1000 -> 8000 | I7: =+(I32-I33)*1000 -> 8500 | J7: =+(J31-J33)*1000 -> 11000 | K7: =+(K31-K33)*1000 -> 12000 | L7: =+(L30-L33)*1000 -> 14000 | M7: =+(M30-M33)*1000 -> 13000 | N7: =+(N30-N33)*1000 -> 13000 | O7: =+(O30-O33)*1000 -> 13000 | P7: =+(P30-P33)*1000 -> 14000 | Q7: =+(Q30-Q33)*1000 -> 15000 | R7: =+(R30-R33)*1000 -> 15000 | S7: =+(S30-S33)*1000 -> 17000 | T7: =+(T30-T33)*1000 -> 17000 | U7: =+(U29-U33)*1000 -> 18000 | V7: =+(V29-V33)*1000 -> 19000 | W7: =+Historical!E6 -> 33 | X7: =+Historical!F6 -> 100 | Y7: =+Historical!G6 -> 149 | Z7: =+Historical!H6 -> 189 | AA7: =+Historical!I6 -> 275 | AB7: =+Historical!J6 -> 231 | AC7: =+Historical!K6 -> 4478 | AD7: =+Historical!L6 -> 6132 | ... AG7: =+Historical!O6 -> 7211
F9: Idea: put figure at scale in grid box
F10: =5000*G10 -> 180000 | G10: =+G11+1 -> 36
F11: =5000*G11 -> 175000 | G11: =+G12+1 -> 35
F12: =5000*G12 -> 170000 | G12: =+G13+1 -> 34 | W12: =+F12 -> 170000
F13: =5000*G13 -> 165000 | G13: =+G14+1 -> 33 | W13: =+F13 -> 165000
F14: =5000*G14 -> 160000 | G14: =+G15+1 -> 32 | W14: =+F14 -> 160000
F15: =5000*G15 -> 155000 | G15: =+G16+1 -> 31 | W15: =+F15 -> 155000
F16: =5000*G16 -> 150000 | G16: =+G17+1 -> 30 | W16: =+F16 -> 150000
F17: =5000*G17 -> 145000 | G17: =+G18+1 -> 29 | W17: =+F17 -> 145000
F18: =5000*G18 -> 140000 | G18: =+G19+1 -> 28 | W18: =+F18 -> 140000
F19: =5000*G19 -> 135000 | G19: =+G20+1 -> 27 | W19: =+F19 -> 135000
F20: =5000*G20 -> 130000 | G20: =+G21+1 -> 26 | U20: 126 | V20: 130 | W20: =+F20 -> 130000
F21: =5000*G21 -> 125000 | G21: =+G22+1 -> 25 | T21: 123 | W21: =+F21 -> 125000
F22: =5000*G22 -> 120000 | G22: =+G23+1 -> 24 | S22: 120 | W22: =+F22 -> 120000
F23: =5000*G23 -> 115000 | G23: =+G24+1 -> 23 | P23: 112 | Q23: 113 | R23: 115 | W23: =+F23 -> 115000
F24: =5000*G24 -> 110000 | G24: =+G25+1 -> 22 | O24: 110 | W24: =+F24 -> 110000
F25: =5000*G25 -> 105000 | G25: =+G26+1 -> 21 | M25: 103 | N25: 105 | W25: =+F25 -> 105000
F26: =5000*G26 -> 100000 | G26: =+G27+1 -> 20 | L26: 100 | S26: 94 | T26: 94 | U26: 96 | V26: 97 | W26: =+F26 -> 100000
F27: =5000*G27 -> 95000 | G27: =+G28+1 -> 19 | K27: 95 | M27: 86 | N27: 87 | O27: 89 | P27: 90 | Q27: 90 | R27: 91 | W27: =+F27 -> 95000
F28: =5000*G28 -> 90000 | G28: =+G29+1 -> 18 | I28: 86.5 | J28: 90 | L28: 85 | W28: =+F28 -> 90000
F29: =5000*G29 -> 85000 | G29: =+G30+1 -> 17 | H29: 82.5 | J29: 81 | K29: 83 | U29: 80 | V29: 81 | W29: =+F29 -> 85000
F30: =5000*G30 -> 80000 | G30: =+G31+1 -> 16 | H30: 75 | I30: 78 | L30: 72 | M30: 72 | N30: 73 | O30: 73 | P30: 74 | Q30: 75 | R30: 75 | S30: 78 | T30: 78 | W30: =+F30 -> 80000
F31: =5000*G31 -> 75000 | G31: =+G32+1 -> 15 | J31: 69 | K31: 70 | W31: =+F31 -> 75000
F32: =5000*G32 -> 70000 | G32: =+G33+1 -> 14 | I32: 66.5 | W32: =+F32 -> 70000
F33: =5000*G33 -> 65000 | G33: =+G34+1 -> 13 | H33: 63 | I33: 58 | J33: 58 | K33: 58 | L33: 58 | M33: 59 | N33: 60 | O33: 60 | P33: 60 | Q33: 60 | R33: 60 | S33: 61 | T33: 61 | U33: 62 | V33: 62 | W33: =+F33 -> 65000
F34: =5000*G34 -> 60000 | G34: =+G35+1 -> 12 | H34: 55 | W34: =+F34 -> 60000
F35: =5000*G35 -> 55000 | G35: =+G36+1 -> 11 | W35: =+F35 -> 55000
F36: =5000*G36 -> 50000 | G36: =+G37+1 -> 10 | W36: =+F36 -> 50000
F37: =5000*G37 -> 45000 | G37: =+G38+1 -> 9 | W37: =+F37 -> 45000
F38: =5000*G38 -> 40000 | G38: =+G39+1 -> 8 | W38: =+F38 -> 40000
F39: =5000*G39 -> 35000 | G39: =+G40+1 -> 7 | W39: =+F39 -> 35000
F40: =5000*G40 -> 30000 | G40: =+G41+1 -> 6 | W40: =+F40 -> 30000
F41: =5000*G41 -> 25000 | G41: =+G42+1 -> 5 | W41: =+F41 -> 25000
...

Sheet Historical
A1: Fuente | B1: https://energia.conahcyt.mx/planeas/electricidad/capacidad-generacion
B2: Capacidad instalada por tecnología (MW)
D4: Type | E4: 2013 | F4: =+E4+1 -> 2014 | G4: =+F4+1 -> 2015 | H4: =+G4+1 -> 2016 | I4: =+H4+1 -> 2017 | J4: =+I4+1 -> 2018 | K4: =+J4+1 -> 2019 | L4: =+K4+1 -> 2020 | M4: =+L4+1 -> 2021 | ... O4: =+N4+1 -> 2023
C5: MW | D5: Wind | E5: 1959 | F5: 2655 | G5: 3233 | H5: 4009 | I5: 4474 | J5: 4677 | K5: 5970 | L5: 6654 | M5: 7354 | N5: 7354 | O5: 7462
D6: Solar | E6: 33 | F6: 100 | G6: 149 | H6: 189 | I6: 275 | J6: 231 | K6: 4478 | L6: 6132 | M6: 6689 | N6: 7209 | O6: 7211
